<?xml version="1.0" ?>
<!-- =================================================================================== -->
<!-- |    This document was autogenerated by xacro from simple_ackermann.xacro         | -->
<!-- |    EDITING THIS FILE BY HAND IS NOT RECOMMENDED                                 | -->
<!-- =================================================================================== -->
<robot name="simple_ackermann" xmlns:xacro="http://www.ros.org/wiki/xacro">
  <!--<xacro:property name="pi" value="3.1415926535897931" />-->
  <link name="base_link">
    <visual name="chassis_visual">
      <origin rpy="0.0 0.0 0.0" xyz="0.0 0.0 0.0"/>
      <geometry name="base_link_geomety">
        <box size="0.26 0.095 0.01"/>
      </geometry>
      <material name="red">
        <color rgba="1.0 0.0 0.0 1.0"/>
      </material>
    </visual>
    <collision>
      <origin rpy="0.0 0.0 0.0" xyz="0.0 0.0 0.0"/>
      <geometry name="base_link_geomety">
        <box size="0.26 0.095 0.01"/>
      </geometry>
    </collision>
    <inertial>
      <mass value="1.0"/>
      <origin xyz="0 0 0"/>
      <inertia ixx="0.0007604163625" ixy="0.0" ixz="0.0" iyy="0.00564166441" iyz="0.0" izz="0.0063854141125"/>
    </inertial>
  </link>
  <gazebo reference="base_link">
    <material value="Gazebo/Red"/>
  </gazebo>
  <joint name="base_link_to_left_rear_wheelmount" type="fixed">
    <origin rpy="0.0 0.0 0.0" xyz="-0.125 0.055 0.0"/>
    <parent link="base_link"/>
    <child link="left_rear_wheelmount"/>
  </joint>
  <link name="left_rear_wheelmount">
    <visual>
      <origin rpy="0.0 0.0 0.0" xyz="0.0 0.0 0.0"/>
      <geometry name="wheelmount_geometry">
        <box size="0.01 0.015 0.01"/>
      </geometry>
      <material name="green">
        <color rgba="0.0 0.75 0.0 1.0"/>
      </material>
    </visual>
    <collision>
      <origin rpy="0.0 0.0 0.0" xyz="0.0 0.0 0.0"/>
      <geometry name="wheelmount_geometry">
        <box size="0.01 0.015 0.01"/>
      </geometry>
    </collision>
    <inertial>
      <mass value="0.015"/>
      <origin xyz="0 0 0"/>
      <inertia ixx="4.062498375e-07" ixy="0.0" ixz="0.0" iyy="2.499999e-07" iyz="0.0" izz="4.062498375e-07"/>
    </inertial>
  </link>
  <gazebo reference="left_rear_wheelmount">
    <material value="Gazebo/Red"/>
  </gazebo>
  <joint name="left_rear_wheel_to_mount" type="continuous">
    <axis xyz="0.0 1.0 0.0"/>
    <origin rpy="0.0 0.0 0.0" xyz="0.0 0.005 0.0"/>
    <parent link="left_rear_wheelmount"/>
    <child link="left_rear_wheel"/>
  </joint>
  <link name="left_rear_wheel">
    <visual>
      <origin rpy="1.57079632679 0.0 0.0" xyz="0.0 0.01375 0.0"/>
      <geometry name="wheel_geom">
        <cylinder length="0.0275" radius="0.0325"/>
      </geometry>
      <material name="black">
        <color rgba="0.0 0.0 0.0 1.0"/>
      </material>
    </visual>
    <collision>
      <origin rpy="1.57079632679 0.0 0.0" xyz="0.0 0.01375 0.0"/>
      <geometry name="wheel_geom">
        <cylinder length="0.0275" radius="0.0325"/>
      </geometry>
    </collision>
    <inertial>
      <mass value="0.01"/>
      <origin rpy="1.57079632679 0.0 0.0" xyz="0.0 0.01375 0.0"/>
      <inertia ixx="3.270832025e-06" ixy="0.0" ixz="0.0" iyy="3.270832025e-06" iyz="0.0" izz="5.28125e-06"/>
    </inertial>
  </link>
  <gazebo reference="left_rear_wheel">
    <mu1>10.0</mu1>
    <mu2>10.0</mu2>
    <kp>1000000.0</kp>
    <kd>10.0</kd>
    <material value="Gazebo/Black"/>
  </gazebo>
  <joint name="base_link_to_right_rear_wheelmount" type="fixed">
    <origin rpy="0.0 0.0 0.0" xyz="-0.125 -0.055 0.0"/>
    <parent link="base_link"/>
    <child link="right_rear_wheelmount"/>
  </joint>
  <link name="right_rear_wheelmount">
    <visual>
      <origin rpy="0.0 0.0 0.0" xyz="0.0 0.0 0.0"/>
      <geometry name="wheelmount_geometry">
        <box size="0.01 0.015 0.01"/>
      </geometry>
      <material name="green">
        <color rgba="0.0 0.75 0.0 1.0"/>
      </material>
    </visual>
    <collision>
      <origin rpy="0.0 0.0 0.0" xyz="0.0 0.0 0.0"/>
      <geometry name="wheelmount_geometry">
        <box size="0.01 0.015 0.01"/>
      </geometry>
    </collision>
    <inertial>
      <mass value="0.015"/>
      <origin xyz="0 0 0"/>
      <inertia ixx="4.062498375e-07" ixy="0.0" ixz="0.0" iyy="2.499999e-07" iyz="0.0" izz="4.062498375e-07"/>
    </inertial>
  </link>
  <gazebo reference="right_rear_wheelmount">
    <material value="Gazebo/Red"/>
  </gazebo>
  <joint name="right_rear_wheel_to_mount" type="continuous">
    <axis xyz="0.0 1.0 0.0"/>
    <origin rpy="0.0 0.0 0.0" xyz="0.0 -0.005 0.0"/>
    <parent link="right_rear_wheelmount"/>
    <child link="right_rear_wheel"/>
  </joint>
  <link name="right_rear_wheel">
    <visual>
      <origin rpy="1.57079632679 0.0 0.0" xyz="0.0 -0.01375 0.0"/>
      <geometry name="wheel_geom">
        <cylinder length="0.0275" radius="0.0325"/>
      </geometry>
      <material name="black">
        <color rgba="0.0 0.0 0.0 1.0"/>
      </material>
    </visual>
    <collision>
      <origin rpy="1.57079632679 0.0 0.0" xyz="0.0 -0.01375 0.0"/>
      <geometry name="wheel_geom">
        <cylinder length="0.0275" radius="0.0325"/>
      </geometry>
    </collision>
    <inertial>
      <mass value="0.01"/>
      <origin rpy="1.57079632679 0.0 0.0" xyz="0.0 -0.01375 0.0"/>
      <inertia ixx="3.270832025e-06" ixy="0.0" ixz="0.0" iyy="3.270832025e-06" iyz="0.0" izz="5.28125e-06"/>
    </inertial>
  </link>
  <gazebo reference="right_rear_wheel">
    <mu1>10.0</mu1>
    <mu2>10.0</mu2>
    <kp>1000000.0</kp>
    <kd>10.0</kd>
    <material value="Gazebo/Black"/>
  </gazebo>
  <joint name="base_link_to_left_front_wheelmount_box" type="fixed">
    <origin rpy="0.0 0.0 0.0" xyz="0.125 0.05 0.0"/>
    <parent link="base_link"/>
    <child link="left_front_wheelmount_box"/>
  </joint>
  <link name="left_front_wheelmount_box">
    <visual>
      <origin rpy="0.0 0.0 0.0" xyz="0.0 0.0 0.0"/>
      <geometry name="wheelmount_geometry">
        <box size="0.01 0.005 0.01"/>
      </geometry>
      <material name="green">
        <color rgba="0.0 0.75 0.0 1.0"/>
      </material>
    </visual>
    <collision>
      <origin rpy="0.0 0.0 0.0" xyz="0.0 0.0 0.0"/>
      <geometry name="wheelmount_geometry">
        <box size="0.01 0.005 0.01"/>
      </geometry>
    </collision>
    <inertial>
      <mass value="0.005"/>
      <origin xyz="0 0 0"/>
      <inertia ixx="5.20833125e-08" ixy="0.0" ixz="0.0" iyy="8.33333e-08" iyz="0.0" izz="5.20833125e-08"/>
    </inertial>
  </link>
  <gazebo reference="left_front_wheelmount_box">
    <material value="Gazebo/Red"/>
  </gazebo>
  <joint name="left_front_wheelmount_box_to_left_front_wheelmount_cylinder" type="fixed">
    <origin rpy="0.0 0.0 0.0" xyz="0.0 0.0025 0.0"/>
    <parent link="left_front_wheelmount_box"/>
    <child link="left_front_wheelmount_cylinder"/>
  </joint>
  <link name="left_front_wheelmount_cylinder">
    <visual>
      <origin rpy="0.0 0.0 0.0" xyz="0.0 0.0 0.0"/>
      <geometry name="wheelmount_geometry">
        <cylinder length="0.01" radius="0.005"/>
      </geometry>
      <material name="green">
        <color rgba="0.0 0.75 0.0 1.0"/>
      </material>
    </visual>
    <collision>
      <origin rpy="0.0 0.0 0.0" xyz="0.0 0.0 0.0"/>
      <geometry name="wheelmount_geometry">
        <cylinder length="0.01" radius="0.005"/>
      </geometry>
    </collision>
    <inertial>
      <mass value="0.005"/>
      <origin rpy="0.0 0.0 0.0" xyz="0.0 0.0 0.0"/>
      <inertia ixx="7.29166375e-08" ixy="0.0" ixz="0.0" iyy="7.29166375e-08" iyz="0.0" izz="6.25e-08"/>
    </inertial>
  </link>
  <gazebo reference="left_front_wheelmount_cylinder">
    <material value="Gazebo/Red"/>
  </gazebo>
  <!--
		<joint name="${side}_front_wheelmount_cylinder_to_${side}_kingpin" type="continuous">
		  	<axis xyz="0.0 0.0 1.0"/>
		  	<origin rpy="0.0 0.0 0.0" xyz="0.0 0.0 0.0"/>
			<parent link="${side}_front_wheelmount_cylinder"/>
			<child link="${side}_kingpin"/>
		</joint>
-->
  <joint name="left_front_wheelmount_cylinder_to_left_kingpin" type="revolute">
    <axis xyz="0.0 0.0 1.0"/>
    <origin rpy="0.0 0.0 0.0" xyz="0.0 0.0 0.0"/>
    <parent link="left_front_wheelmount_cylinder"/>
    <child link="left_kingpin"/>
    <limit effort="100" lower="-0.4" upper="0.4" velocity="100"/>
    <joint_properties damping="1.0" friction="0.0"/>
  </joint>
  <link name="left_kingpin">
    <visual>
      <origin rpy="0.0 0.0 0.0" xyz="0.0 0.0075 0.0"/>
      <geometry name="kingpin_geometry">
        <box size="0.01 0.005 0.01"/>
      </geometry>
      <material name="orange">
        <color rgba="1.0 0.5 0.0 1.0"/>
      </material>
    </visual>
    <collision>
      <origin rpy="0.0 0.0 0.0" xyz="0.0 0.0075 0.0"/>
      <geometry name="kingpin_geometry">
        <box size="0.01 0.005 0.01"/>
      </geometry>
    </collision>
    <inertial>
      <mass value="0.005"/>
      <origin rpy="0.0 0.0 0.0" xyz="0.0 0.0075 0.0"/>
      <inertia ixx="5.20833125e-08" ixy="0.0" ixz="0.0" iyy="8.33333e-08" iyz="0.0" izz="5.20833125e-08"/>
    </inertial>
  </link>
  <gazebo reference="left_kingpin">
    <material value="Gazebo/Orange"/>
  </gazebo>
  <joint name="left_kingpin_to_left_front_wheel" type="continuous">
    <axis xyz="0.0 1.0 0.0"/>
    <origin rpy="0.0 0.0 0.0" xyz="0.0 0.01 0.0"/>
    <parent link="left_kingpin"/>
    <child link="left_front_wheel"/>
  </joint>
  <link name="left_front_wheel">
    <visual>
      <origin rpy="1.57079632679 0.0 0.0" xyz="0.0 0.01375 0.0"/>
      <geometry name="wheel_geom">
        <cylinder length="0.0275" radius="0.0325"/>
      </geometry>
      <material name="black">
        <color rgba="0.0 0.0 0.0 1.0"/>
      </material>
    </visual>
    <collision>
      <origin rpy="1.57079632679 0.0 0.0" xyz="0.0 0.01375 0.0"/>
      <geometry name="wheel_geom">
        <cylinder length="0.0275" radius="0.0325"/>
      </geometry>
    </collision>
    <inertial>
      <mass value="0.01"/>
      <origin rpy="1.57079632679 0.0 0.0" xyz="0.0 0.01375 0.0"/>
      <inertia ixx="3.270832025e-06" ixy="0.0" ixz="0.0" iyy="3.270832025e-06" iyz="0.0" izz="5.28125e-06"/>
    </inertial>
  </link>
  <gazebo reference="left_front_wheel">
    <mu1>10.0</mu1>
    <!-- friction coeffciant 1 -->
    <mu2>10.0</mu2>
    <!-- friction coeffciant 2 -->
    <kp>1000000.0</kp>
    <!-- contact stiffness 	-->
    <kd>10.0</kd>
    <!-- cantact damping 	-->
    <material value="Gazebo/Black"/>
  </gazebo>
  <joint name="base_link_to_right_front_wheelmount_box" type="fixed">
    <origin rpy="0.0 0.0 0.0" xyz="0.125 -0.05 0.0"/>
    <parent link="base_link"/>
    <child link="right_front_wheelmount_box"/>
  </joint>
  <link name="right_front_wheelmount_box">
    <visual>
      <origin rpy="0.0 0.0 0.0" xyz="0.0 0.0 0.0"/>
      <geometry name="wheelmount_geometry">
        <box size="0.01 0.005 0.01"/>
      </geometry>
      <material name="green">
        <color rgba="0.0 0.75 0.0 1.0"/>
      </material>
    </visual>
    <collision>
      <origin rpy="0.0 0.0 0.0" xyz="0.0 0.0 0.0"/>
      <geometry name="wheelmount_geometry">
        <box size="0.01 0.005 0.01"/>
      </geometry>
    </collision>
    <inertial>
      <mass value="0.005"/>
      <origin xyz="0 0 0"/>
      <inertia ixx="5.20833125e-08" ixy="0.0" ixz="0.0" iyy="8.33333e-08" iyz="0.0" izz="5.20833125e-08"/>
    </inertial>
  </link>
  <gazebo reference="right_front_wheelmount_box">
    <material value="Gazebo/Red"/>
  </gazebo>
  <joint name="right_front_wheelmount_box_to_right_front_wheelmount_cylinder" type="fixed">
    <origin rpy="0.0 0.0 0.0" xyz="0.0 -0.0025 0.0"/>
    <parent link="right_front_wheelmount_box"/>
    <child link="right_front_wheelmount_cylinder"/>
  </joint>
  <link name="right_front_wheelmount_cylinder">
    <visual>
      <origin rpy="0.0 0.0 0.0" xyz="0.0 0.0 0.0"/>
      <geometry name="wheelmount_geometry">
        <cylinder length="0.01" radius="0.005"/>
      </geometry>
      <material name="green">
        <color rgba="0.0 0.75 0.0 1.0"/>
      </material>
    </visual>
    <collision>
      <origin rpy="0.0 0.0 0.0" xyz="0.0 0.0 0.0"/>
      <geometry name="wheelmount_geometry">
        <cylinder length="0.01" radius="0.005"/>
      </geometry>
    </collision>
    <inertial>
      <mass value="0.005"/>
      <origin rpy="0.0 0.0 0.0" xyz="0.0 0.0 0.0"/>
      <inertia ixx="7.29166375e-08" ixy="0.0" ixz="0.0" iyy="7.29166375e-08" iyz="0.0" izz="6.25e-08"/>
    </inertial>
  </link>
  <gazebo reference="right_front_wheelmount_cylinder">
    <material value="Gazebo/Red"/>
  </gazebo>
  <!--
		<joint name="${side}_front_wheelmount_cylinder_to_${side}_kingpin" type="continuous">
		  	<axis xyz="0.0 0.0 1.0"/>
		  	<origin rpy="0.0 0.0 0.0" xyz="0.0 0.0 0.0"/>
			<parent link="${side}_front_wheelmount_cylinder"/>
			<child link="${side}_kingpin"/>
		</joint>
-->
  <joint name="right_front_wheelmount_cylinder_to_right_kingpin" type="revolute">
    <axis xyz="0.0 0.0 1.0"/>
    <origin rpy="0.0 0.0 0.0" xyz="0.0 0.0 0.0"/>
    <parent link="right_front_wheelmount_cylinder"/>
    <child link="right_kingpin"/>
    <limit effort="100" lower="-0.4" upper="0.4" velocity="100"/>
    <joint_properties damping="1.0" friction="0.0"/>
  </joint>
  <link name="right_kingpin">
    <visual>
      <origin rpy="0.0 0.0 0.0" xyz="0.0 -0.0075 0.0"/>
      <geometry name="kingpin_geometry">
        <box size="0.01 0.005 0.01"/>
      </geometry>
      <material name="orange">
        <color rgba="1.0 0.5 0.0 1.0"/>
      </material>
    </visual>
    <collision>
      <origin rpy="0.0 0.0 0.0" xyz="0.0 -0.0075 0.0"/>
      <geometry name="kingpin_geometry">
        <box size="0.01 0.005 0.01"/>
      </geometry>
    </collision>
    <inertial>
      <mass value="0.005"/>
      <origin rpy="0.0 0.0 0.0" xyz="0.0 -0.0075 0.0"/>
      <inertia ixx="5.20833125e-08" ixy="0.0" ixz="0.0" iyy="8.33333e-08" iyz="0.0" izz="5.20833125e-08"/>
    </inertial>
  </link>
  <gazebo reference="right_kingpin">
    <material value="Gazebo/Orange"/>
  </gazebo>
  <joint name="right_kingpin_to_right_front_wheel" type="continuous">
    <axis xyz="0.0 1.0 0.0"/>
    <origin rpy="0.0 0.0 0.0" xyz="0.0 -0.01 0.0"/>
    <parent link="right_kingpin"/>
    <child link="right_front_wheel"/>
  </joint>
  <link name="right_front_wheel">
    <visual>
      <origin rpy="1.57079632679 0.0 0.0" xyz="0.0 -0.01375 0.0"/>
      <geometry name="wheel_geom">
        <cylinder length="0.0275" radius="0.0325"/>
      </geometry>
      <material name="black">
        <color rgba="0.0 0.0 0.0 1.0"/>
      </material>
    </visual>
    <collision>
      <origin rpy="1.57079632679 0.0 0.0" xyz="0.0 -0.01375 0.0"/>
      <geometry name="wheel_geom">
        <cylinder length="0.0275" radius="0.0325"/>
      </geometry>
    </collision>
    <inertial>
      <mass value="0.01"/>
      <origin rpy="1.57079632679 0.0 0.0" xyz="0.0 -0.01375 0.0"/>
      <inertia ixx="3.270832025e-06" ixy="0.0" ixz="0.0" iyy="3.270832025e-06" iyz="0.0" izz="5.28125e-06"/>
    </inertial>
  </link>
  <gazebo reference="right_front_wheel">
    <mu1>10.0</mu1>
    <!-- friction coeffciant 1 -->
    <mu2>10.0</mu2>
    <!-- friction coeffciant 2 -->
    <kp>1000000.0</kp>
    <!-- contact stiffness 	-->
    <kd>10.0</kd>
    <!-- cantact damping 	-->
    <material value="Gazebo/Black"/>
  </gazebo>
  <gazebo>
    <plugin filename="libackermanndrive_plugin.so" name="ackermanndrive_plugin">
      <rosDebugLevel>Debug</rosDebugLevel>
      <robotNamespace>ackermann</robotNamespace>
      <CommandTopic>command</CommandTopic>
      <OdometryTopicEncoder>odometry_encoder</OdometryTopicEncoder>
      <OdometryTopicGodview>odometry_godview</OdometryTopicGodview>
      <odometryFrame>odom</odometryFrame>
      <robotBaseFrame>base_link</robotBaseFrame>
      <Wheelbase>0.26</Wheelbase>
      <Track>0.1525</Track>
      <Wheeldiameter>0.0325</Wheeldiameter>
      <Steeringvelocity>25.0</Steeringvelocity>
      <Streeringtorque>1.0</Streeringtorque>
      <Steeringangle>0.4</Steeringangle>
      <Wheeltorque>0.1</Wheeltorque>
      <LeftSteering>left_front_wheelmount_cylinder_to_left_kingpin</LeftSteering>
      <RightSteering>right_front_wheelmount_cylinder_to_right_kingpin</RightSteering>
      <LeftFrontWheel>left_kingpin_to_left_front_wheel</LeftFrontWheel>
      <RightFrontWheel>right_kingpin_to_right_front_wheel</RightFrontWheel>
      <LeftRearWheel>left_rear_wheel_to_mount</LeftRearWheel>
      <RightRearWheel>right_rear_wheel_to_mount</RightRearWheel>
    </plugin>
  </gazebo>
</robot>

